# 47장. 에러 처리
## 47.1 에러 처리의 필요성
에러를 방치하면 프로그램이 강제 종료된다.
```js
console.log('[Start]')

foo() // ReferenceError: foo is not defined
// 발생한 에러를 방치하면 프로그램은 강제 종료된다.

// 에러에 의해 프로그램이 강제 종료되어 아래 코드는 실행되지 않는다.
console.log('[End]')
```
try...catch문을 사용하면 프로그램이 강제종료되지 않고 대응할 수 있다.
```js
console.log('[Start]')

try {
  foo()
} catch (error) {
  console.error('[에러 발생]', error)
  // [에러 발생] ReferenceError: foo is not defined
}

// 발생한 에러에 적절한 대응을 하면 프로그램이 강제 종료되지 않는다.
console.log('[End]')
```
에러를 발생하지 않는 예외적인 상황에 대응하지 않으면 에러로 이어질 수 있다.
```js
// DOM에 button 요소가 존재하지 않으면 querySelector 메서드는 에러를 발생시키지 않고 null을 반환한다.
const $button = document.querySelector('button') // null

$button.classList.add('disabled')
// TypeError: Cannot read property 'classList' of null
```
인수로 전달한 문자열이 CSS 선택자 문법에 맞지 않는경우 에러를 발생하지만, CSS 선택자 문자열로 DOM에서 요소 노드를 찾을 수 없는 경우 에러를 발생시키지 않고 null을 반환한다. 이떄 반환값을 확인하거나 단축 평가, 옵셔널 체이닝 연산자를 사용하지 않으면 다음 처리에서 에러로 이어진다.
```js
const $elem = document.querySelector('#1')
// DOMException: Failed to execute 'querySelector' on 'Document': '#1' is not a valid selector.

// DOM에 button 요소가 존재하는 경우 querySelector 메서드는 에러를 발생시키지 않고 null을 반환한다.
const $button = document.querySelector('button') // null
$button?.classList.add('disabled')
```
에러 상황에 대응하지 않으면 프로그램은 강제 종료된다. 강제 종료가 된다면 에러의 원인을 파악하기 어렵다. 따라서 에러나 예외적인 상황이 발생할 수 있다는 것을 전제로 이에 대응하는 코드를 작성하는 것은 중요하다.
## 47.2 try...catch...finally 문
에러를 처리하는 방법은 두개가 있다. 첫번쨰는 if문이나 단축평가 또는 옵셔널 체이닝 연산자를 통해 확인해서 처리하는 방법과 에러처리 코드를 미리 등록해두고 에러가 발생하면 에러 처리 코드로 점프하는 방법이다.   
try...catch...finally는 두번째 방법으로 일반적인 에러 처리 방법이다. finally와 catch는 생략 가능하지만 catch가 생략된다면 try문의 의미가 없으므로 생략하지 않는다.   
try...catch...finally는 try 블록이 먼저 실행되고 에러가 발생하면 에러는 catch의 err변수에 전달되고 catch 블록이 실행된다. finally 코드 블록은 에러 발생과 상관없이 반드시 한번 실행된다.
```js
console.log('[Start]')

try {
  // 실행할 코드(에러가 발생할 가능성이 있는 코드)
  foo()
} catch (err) {
  // try 코드 블록에서 에러가 발생하면 이 코드 블록의 코드가 실행된다.
  // err에는 try 코드 블록에서 발생한 Error 객체가 전달된다.
  console.error(err) // ReferenceError: foo is not defined
} finally {
  // 에러 발생과 상관없이 반드시 한 번 실행된다.
  console.log('finally')
}

// try...catch...finally 문으로 에러를 처리하면 프로그램이 강제 종료되지 않는다.
console.log('[End]')
```
## 47.3 Error 객체
Error 생성자 함수는 에러 객체를 생성한다.
```js
const error = new Error('invalid')
```
에러 객체는 message 프로퍼티와 stack 프로퍼티를 갖는다. message 프로퍼티의 값은 Error 생성자 함수에 인수로 전달한 에러 메세지고, stack 프로퍼티의 값은 에러를 발생시킨 콜스택의 호출 정보를 나타내는 문자열이다.   
에러 객체는 7가지가 있다.
|생성자 함수|인스턴스|
|---|---|
|Error|일반적 에러 객체|
|SyntaxError|자바스크립트 문법에 맞지 않는 문을 해석할 떄 발생하는 에러 객체|
|ReferenceError|참조할 수 없는 식별자를 참조했을때 발생하는 에러 객체|
|TypeError|피연산자 또는 인수의 데이터 타입이 유효하지 않을 떄 발생하는 에러 객체|
|RangeError|숫자값의 허용 범위를 벗어났을 떄 발생하는 에러 객체|
|URIError|encodeURI또는 decodeURI 함수에 부적절한 인수를 전달했을 떄 발생하는 에러 객체|
|EvalError|eval 함수에서 발생하는 에러 객체|
```js
1 @ 1    // SyntaxError: Invalid or unexpected token
foo()    // ReferenceError: foo is not defined
null.foo // TypeError: Cannot read property 'foo' of null
new Array(-1) // RangeError: Invalid array length
decodeURIComponent('%') // URIError: URI malformed
```
## 47.4 throw 문
Error 생성자 함수로 에러 객체를 생성했다고 에러가 발생하는 것은 아니다.
```js
try {
  // 에러 객체를 생성한다고 에러가 발생하는 것은 아니다.
  new Error('something wrong')
} catch (error) {
  console.log(error)
}
```
에러를 발생하려면 try 블록에서 throw문으로 에러 객체를 던져야한다,
throw문의 표현식은 어떤 값이라도 상관없지만 일반적으로 에러 객체를 지정한다. 
```js
// 외부에서 전달받은 콜백 함수를 n번만큼 반복 호출한다
const repeat = (n, f) => {
  // 매개변수 f에 전달된 인수가 함수가 아니면 TypeError를 발생시킨다.
  if (typeof f !== 'function') throw new TypeError('f must be a function')

  for (var i = 0 i < n i++) {
    f(i) // i를 전달하면서 f를 호출
  }
}

try {
  repeat(2, 1) // 두 번째 인수가 함수가 아니므로 TypeError가 발생(throw)한다.
} catch (err) {
  console.error(err) // TypeError: f must be a function
}
```
## 47.5 에러의 전파
에러는 호출자 방향으로 전파된다. 즉, 콜스택의 아래 방향으로 전파된다.
```js
const foo = () => {
  throw Error('foo에서 발생한 에러') // ④
}

const bar = () => {
  foo() // ③
}

const baz = () => {
  bar() // ②
}

try {
  baz() // ①
} catch (err) {
  console.error(err)
}
``` 
1에서 baz 함수를 호출하면 2에서 bar함수가 호출되고 3에서 foo함수가 호출되고 foo함수는 4에서 에러를 throw 한다. foo에서 throw한 에러는 호출자에게 전파되어 전역에서 캐치된다.   
throw된 에러를 캐치하지 않으면 호출자 방향으로 전파되고 이때 에러를 캐치하여 적절히 대응하면 프로그램을 종료시키지 않고 코드의 실행 흐름을 복구할 수 있다.   
주의할것은 비동기함수나 프로미스 후속 처리 메서드의 콜백 함수는 호출자가 없다.